2025-03-18 00:36:28,749 - PythonTestLogger - ERROR - Test failed for QA2_P3_P4.py on QA2

SRNs: P3/P4

Error:
Traceback (most recent call last):
  File "/Volumes/Aditya SSD/Project/AutomaticPythonTesting/AutomaticPythonTesting/scripts/QA2_P3_P4.py", line 119, in <module>
    main()  
    ^^^^^^
  File "/Volumes/Aditya SSD/Project/AutomaticPythonTesting/AutomaticPythonTesting/scripts/QA2_P3_P4.py", line 111, in main
    P, L, U, x = decompose_and_solve(A, b)  
                 ^^^^^^^^^^^^^^^^^^^^^^^^^
  File "/Volumes/Aditya SSD/Project/AutomaticPythonTesting/AutomaticPythonTesting/scripts/QA2_P3_P4.py", line 97, in decompose_and_solve
    return P, L, U, x  
           ^
NameError: name 'P' is not defined


Test Type: stdin

Test Input:
3
1 2 3
4 5 6
7 8 9
10 11 12

Expected Output:
P (3x3):
 [[0. 1. 0.]
 [0. 0. 1.]
 [1. 0. 0.]]
L (3x3):
 [[1.   0.   0.  ]
 [0.14 1.   0.  ]
 [0.57 0.5  1.  ]]
U (3x3):
 [[ 7.    8.    9.  ]
 [ 0.    0.86  1.71]
 [ 0.    0.   -0.  ]]
Force magnitudes: [-25.33  41.67 -16.  ]
--------------------------------------------------
2025-03-18 00:36:29,067 - PythonTestLogger - ERROR - Test failed for QA2_P3_P4.py on QA2

SRNs: P3/P4

Error:
Traceback (most recent call last):
  File "/Volumes/Aditya SSD/Project/AutomaticPythonTesting/AutomaticPythonTesting/scripts/QA2_P3_P4.py", line 119, in <module>
    main()  
    ^^^^^^
  File "/Volumes/Aditya SSD/Project/AutomaticPythonTesting/AutomaticPythonTesting/scripts/QA2_P3_P4.py", line 111, in main
    P, L, U, x = decompose_and_solve(A, b)  
                 ^^^^^^^^^^^^^^^^^^^^^^^^^
  File "/Volumes/Aditya SSD/Project/AutomaticPythonTesting/AutomaticPythonTesting/scripts/QA2_P3_P4.py", line 97, in decompose_and_solve
    return P, L, U, x  
           ^
NameError: name 'P' is not defined


Test Type: stdin

Test Input:
4
2  -1   0   0
-1  2  -1   0
0  -1   2  -1
0   0  -1   2
1  0  1  0

Expected Output:
P (4x4):
 [[1. 0. 0. 0.]
 [0. 1. 0. 0.]
 [0. 0. 1. 0.]
 [0. 0. 0. 1.]]
L (4x4):
 [[ 1.    0.    0.    0.  ]
 [-0.5   1.    0.    0.  ]
 [ 0.   -0.67  1.    0.  ]
 [ 0.    0.   -0.75  1.  ]]
U (4x4):
 [[ 2.   -1.    0.    0.  ]
 [ 0.    1.5  -1.    0.  ]
 [ 0.    0.    1.33 -1.  ]
 [ 0.    0.    0.    1.25]]
Force magnitudes: [1.2 1.4 1.6 0.8]
--------------------------------------------------
2025-03-18 00:36:29,389 - PythonTestLogger - ERROR - Test failed for QA2_P3_P4.py on QA2

SRNs: P3/P4

Error:
Traceback (most recent call last):
  File "/Volumes/Aditya SSD/Project/AutomaticPythonTesting/AutomaticPythonTesting/scripts/QA2_P3_P4.py", line 119, in <module>
    main()  
    ^^^^^^
  File "/Volumes/Aditya SSD/Project/AutomaticPythonTesting/AutomaticPythonTesting/scripts/QA2_P3_P4.py", line 111, in main
    P, L, U, x = decompose_and_solve(A, b)  
                 ^^^^^^^^^^^^^^^^^^^^^^^^^
  File "/Volumes/Aditya SSD/Project/AutomaticPythonTesting/AutomaticPythonTesting/scripts/QA2_P3_P4.py", line 97, in decompose_and_solve
    return P, L, U, x  
           ^
NameError: name 'P' is not defined


Test Type: stdin

Test Input:
5
3  1  0  2  1
1  4  2  0  1
0  2  5  1  0
2  0  1  6  2
1  1  0  2  7
10  20  30  40  50


Expected Output:
P (5x5):
 [[1. 0. 0. 0. 0.]
 [0. 1. 0. 0. 0.]
 [0. 0. 1. 0. 0.]
 [0. 0. 0. 1. 0.]
 [0. 0. 0. 0. 1.]]
L (5x5):
 [[ 1.    0.    0.    0.    0.  ]
 [ 0.33  1.    0.    0.    0.  ]
 [ 0.    0.55  1.    0.    0.  ]
 [ 0.67 -0.18  0.35  1.    0.  ]
 [ 0.33  0.18 -0.09  0.39  1.  ]]
U (5x5):
 [[ 3.    1.    0.    2.    1.  ]
 [ 0.    3.67  2.   -0.67  0.67]
 [ 0.    0.    3.91  1.36 -0.36]
 [ 0.    0.    0.    4.07  1.58]
 [ 0.    0.    0.    0.    5.9 ]]
Force magnitudes: [-2.56  2.09  4.19  4.88  5.81]
--------------------------------------------------
2025-03-18 00:36:31,430 - PythonTestLogger - ERROR - Test failed for QA1_P1_P2.py on QA1

SRNs: P1/P2

Error:
Traceback (most recent call last):
  File "/Volumes/Aditya SSD/Project/AutomaticPythonTesting/AutomaticPythonTesting/scripts/QA1_P1_P2.py", line 160, in <module>
    main()
  File "/Volumes/Aditya SSD/Project/AutomaticPythonTesting/AutomaticPythonTesting/scripts/QA1_P1_P2.py", line 147, in main
    L, U = lu_decomposition(A)
           ^^^^^^^^^^^^^^^^^^^
  File "/Volumes/Aditya SSD/Project/AutomaticPythonTesting/AutomaticPythonTesting/scripts/QA1_P1_P2.py", line 115, in lu_decomposition
    return L,U
           ^
NameError: name 'L' is not defined


Test Type: stdin

Test Input:
3
2 -1 -2
-4 6 3
-4 -2 8
3 7 10

Expected Output:
L =
[[ 1.    0.    0.  ]
 [ 1.    1.    0.  ]
 [-0.5  -0.25  1.  ]]

U =
[[-4.    6.    3.  ]
 [ 0.   -8.    5.  ]
 [ 0.    0.    0.75]]

x =
26.62 9.92 16.67
--------------------------------------------------
2025-03-18 00:36:32,280 - PythonTestLogger - ERROR - Test failed for QA1_P1_P2.py on QA1

SRNs: P1/P2

Error:
Traceback (most recent call last):
  File "/Volumes/Aditya SSD/Project/AutomaticPythonTesting/AutomaticPythonTesting/scripts/QA1_P1_P2.py", line 160, in <module>
    main()
  File "/Volumes/Aditya SSD/Project/AutomaticPythonTesting/AutomaticPythonTesting/scripts/QA1_P1_P2.py", line 147, in main
    L, U = lu_decomposition(A)
           ^^^^^^^^^^^^^^^^^^^
  File "/Volumes/Aditya SSD/Project/AutomaticPythonTesting/AutomaticPythonTesting/scripts/QA1_P1_P2.py", line 115, in lu_decomposition
    return L,U
           ^
NameError: name 'L' is not defined


Test Type: stdin

Test Input:
4
4  1  0  2
1  5  3 -1
2  0  6  1
3  2  1  7
10 8 15 20

Expected Output:
L =
[[ 1.    0.    0.    0.  ]
 [ 0.25  1.    0.    0.  ]
 [ 0.5  -0.11  1.    0.  ]
 [ 0.75  0.26  0.03  1.  ]]

U =
[[ 4.    1.    0.    2.  ]
 [ 0.    4.75  3.   -1.5 ]
 [ 0.    0.    6.32 -0.16]
 [ 0.    0.    0.    5.9 ]]

x =
1.43 0.64 1.72 1.81
--------------------------------------------------
2025-03-18 00:36:33,116 - PythonTestLogger - ERROR - Test failed for QA1_P1_P2.py on QA1

SRNs: P1/P2

Error:
Traceback (most recent call last):
  File "/Volumes/Aditya SSD/Project/AutomaticPythonTesting/AutomaticPythonTesting/scripts/QA1_P1_P2.py", line 160, in <module>
    main()
  File "/Volumes/Aditya SSD/Project/AutomaticPythonTesting/AutomaticPythonTesting/scripts/QA1_P1_P2.py", line 147, in main
    L, U = lu_decomposition(A)
           ^^^^^^^^^^^^^^^^^^^
  File "/Volumes/Aditya SSD/Project/AutomaticPythonTesting/AutomaticPythonTesting/scripts/QA1_P1_P2.py", line 115, in lu_decomposition
    return L,U
           ^
NameError: name 'L' is not defined


Test Type: stdin

Test Input:
5
5  2  1  0  3
2  6  0  1 -1
1  0  7  2  4
0  1  2  8  0
3 -1  4  0  9
12 8 25 18 30

Expected Output:
L =
[[ 1.    0.    0.    0.    0.  ]
 [ 0.4   1.    0.    0.    0.  ]
 [ 0.2  -0.08  1.    0.    0.  ]
 [ 0.    0.19  0.31  1.    0.  ]
 [ 0.6  -0.42  0.48 -0.08  1.  ]]

U =
[[ 5.    2.    1.    0.    3.  ]
 [ 0.    5.2  -0.4   1.   -2.2 ]
 [ 0.    0.    6.77  2.08  3.23]
 [ 0.    0.    0.    7.17 -0.57]
 [ 0.    0.    0.    0.    4.68]]

x =
-0.36 1.67 1.42 1.69 3.01
--------------------------------------------------
2025-03-18 00:36:33,456 - PythonTestLogger - ERROR - Test failed for QA3_P5_P6.py on QA3

SRNs: P5/P6

Error:
Traceback (most recent call last):
  File "/Volumes/Aditya SSD/Project/AutomaticPythonTesting/AutomaticPythonTesting/scripts/QA3_P5_P6.py", line 90, in <module>
    main()  
    ^^^^^^
  File "/Volumes/Aditya SSD/Project/AutomaticPythonTesting/AutomaticPythonTesting/scripts/QA3_P5_P6.py", line 84, in main
    params, residual = calibrate_sensor(A, b)  
                       ^^^^^^^^^^^^^^^^^^^^^^
  File "/Volumes/Aditya SSD/Project/AutomaticPythonTesting/AutomaticPythonTesting/scripts/QA3_P5_P6.py", line 72, in calibrate_sensor
    return x, residual
           ^
NameError: name 'x' is not defined


Test Type: stdin

Test Input:
5  
0.8 1.2  
1.0 1.5  
1.2 1.8  
0.9 1.3  
1.1 1.6  
4.1 5.0 5.9 4.8 5.7  

Expected Output:
Best-fit parameters: [12.97 -5.32]
Residual error: [-0.11 -0.02  0.08 -0.05  0.05]
--------------------------------------------------
2025-03-18 00:36:33,785 - PythonTestLogger - ERROR - Test failed for QA3_P5_P6.py on QA3

SRNs: P5/P6

Error:
Traceback (most recent call last):
  File "/Volumes/Aditya SSD/Project/AutomaticPythonTesting/AutomaticPythonTesting/scripts/QA3_P5_P6.py", line 90, in <module>
    main()  
    ^^^^^^
  File "/Volumes/Aditya SSD/Project/AutomaticPythonTesting/AutomaticPythonTesting/scripts/QA3_P5_P6.py", line 84, in main
    params, residual = calibrate_sensor(A, b)  
                       ^^^^^^^^^^^^^^^^^^^^^^
  File "/Volumes/Aditya SSD/Project/AutomaticPythonTesting/AutomaticPythonTesting/scripts/QA3_P5_P6.py", line 72, in calibrate_sensor
    return x, residual
           ^
NameError: name 'x' is not defined


Test Type: stdin

Test Input:
3  
1 1  
1 2  
1 3  
3 5 7  

Expected Output:
Best-fit parameters: [1. 2.]
Residual error: [0. 0. 0.]
--------------------------------------------------
2025-03-18 00:36:34,107 - PythonTestLogger - ERROR - Test failed for QA3_P5_P6.py on QA3

SRNs: P5/P6

Error:
Traceback (most recent call last):
  File "/Volumes/Aditya SSD/Project/AutomaticPythonTesting/AutomaticPythonTesting/scripts/QA3_P5_P6.py", line 90, in <module>
    main()  
    ^^^^^^
  File "/Volumes/Aditya SSD/Project/AutomaticPythonTesting/AutomaticPythonTesting/scripts/QA3_P5_P6.py", line 84, in main
    params, residual = calibrate_sensor(A, b)  
                       ^^^^^^^^^^^^^^^^^^^^^^
  File "/Volumes/Aditya SSD/Project/AutomaticPythonTesting/AutomaticPythonTesting/scripts/QA3_P5_P6.py", line 72, in calibrate_sensor
    return x, residual
           ^
NameError: name 'x' is not defined


Test Type: stdin

Test Input:
4  
1 0 2  
0 1 3  
2 3 1  
3 2 0  
4 6 14 12

Expected Output:
Best-fit parameters: [2. 3. 1.]
Residual error: [ 0.  0. -0.  0.]
--------------------------------------------------
2025-03-18 00:36:34,429 - PythonTestLogger - ERROR - Test failed for QA3_P5_P6.py on QA3

SRNs: P5/P6

Error:
Traceback (most recent call last):
  File "/Volumes/Aditya SSD/Project/AutomaticPythonTesting/AutomaticPythonTesting/scripts/QA3_P5_P6.py", line 90, in <module>
    main()  
    ^^^^^^
  File "/Volumes/Aditya SSD/Project/AutomaticPythonTesting/AutomaticPythonTesting/scripts/QA3_P5_P6.py", line 84, in main
    params, residual = calibrate_sensor(A, b)  
                       ^^^^^^^^^^^^^^^^^^^^^^
  File "/Volumes/Aditya SSD/Project/AutomaticPythonTesting/AutomaticPythonTesting/scripts/QA3_P5_P6.py", line 72, in calibrate_sensor
    return x, residual
           ^
NameError: name 'x' is not defined


Test Type: stdin

Test Input:
8  
5 3 7 2 8  
9 1 4 6 3  
2 8 5 7 1  
6 4 9 3 2  
7 5 8 1 4  
3 6 2 9 5  
8 2 6 4 7  
1 7 3 5 9  
45 32 28 37 41 29 34 40  

Expected Output:
Best-fit parameters: [1.13 1.56 2.06 0.26 2.11]
Residual error: [-2.81 -4.09  0.96 -0.39 -0.06  0.74  6.38 -1.5 ]
--------------------------------------------------
2025-03-18 00:36:34,692 - PythonTestLogger - ERROR - Test failed for QA4_P7_P8.py on QA4

SRNs: P7/P8

Error:
Traceback (most recent call last):
  File "/Volumes/Aditya SSD/Project/AutomaticPythonTesting/AutomaticPythonTesting/scripts/QA4_P7_P8.py", line 78, in <module>
    is_singular, inv_matrix = analyze_sensor_matrix(A)
                              ^^^^^^^^^^^^^^^^^^^^^^^^
  File "/Volumes/Aditya SSD/Project/AutomaticPythonTesting/AutomaticPythonTesting/scripts/QA4_P7_P8.py", line 68, in analyze_sensor_matrix
    return (is_singular, inv_matrix)
            ^^^^^^^^^^^
NameError: name 'is_singular' is not defined


Test Type: stdin

Test Input:
3
1 2 3
0 1 4
5 6 0

Expected Output:
The matrix is not singular.
Inverse of the matrix: 
[[-24.  18.   5.]
 [ 20. -15.  -4.]
 [ -5.   4.   1.]]
--------------------------------------------------
2025-03-18 00:36:34,959 - PythonTestLogger - ERROR - Test failed for QA4_P7_P8.py on QA4

SRNs: P7/P8

Error:
Traceback (most recent call last):
  File "/Volumes/Aditya SSD/Project/AutomaticPythonTesting/AutomaticPythonTesting/scripts/QA4_P7_P8.py", line 78, in <module>
    is_singular, inv_matrix = analyze_sensor_matrix(A)
                              ^^^^^^^^^^^^^^^^^^^^^^^^
  File "/Volumes/Aditya SSD/Project/AutomaticPythonTesting/AutomaticPythonTesting/scripts/QA4_P7_P8.py", line 68, in analyze_sensor_matrix
    return (is_singular, inv_matrix)
            ^^^^^^^^^^^
NameError: name 'is_singular' is not defined


Test Type: stdin

Test Input:
3
2 4 6
1 2 3
3 6 9

Expected Output:
The matrix is singular.
--------------------------------------------------
2025-03-18 00:36:35,232 - PythonTestLogger - ERROR - Test failed for QA4_P7_P8.py on QA4

SRNs: P7/P8

Error:
Traceback (most recent call last):
  File "/Volumes/Aditya SSD/Project/AutomaticPythonTesting/AutomaticPythonTesting/scripts/QA4_P7_P8.py", line 78, in <module>
    is_singular, inv_matrix = analyze_sensor_matrix(A)
                              ^^^^^^^^^^^^^^^^^^^^^^^^
  File "/Volumes/Aditya SSD/Project/AutomaticPythonTesting/AutomaticPythonTesting/scripts/QA4_P7_P8.py", line 68, in analyze_sensor_matrix
    return (is_singular, inv_matrix)
            ^^^^^^^^^^^
NameError: name 'is_singular' is not defined


Test Type: stdin

Test Input:
4
1 2 3
4 5 6
7 8 9
10 11 12

Expected Output:
The matrix is not singular.
Inverse of the matrix: 
[[-0.48 -0.24 -0.01  0.23]
 [-0.03 -0.01  0.01  0.03]
 [ 0.42  0.22  0.03 -0.17]]
--------------------------------------------------
2025-03-18 00:36:35,490 - PythonTestLogger - ERROR - Test failed for QA4_P7_P8.py on QA4

SRNs: P7/P8

Error:
Traceback (most recent call last):
  File "/Volumes/Aditya SSD/Project/AutomaticPythonTesting/AutomaticPythonTesting/scripts/QA4_P7_P8.py", line 78, in <module>
    is_singular, inv_matrix = analyze_sensor_matrix(A)
                              ^^^^^^^^^^^^^^^^^^^^^^^^
  File "/Volumes/Aditya SSD/Project/AutomaticPythonTesting/AutomaticPythonTesting/scripts/QA4_P7_P8.py", line 68, in analyze_sensor_matrix
    return (is_singular, inv_matrix)
            ^^^^^^^^^^^
NameError: name 'is_singular' is not defined


Test Type: stdin

Test Input:
3
1 2 3 4
5 6 7 8
9 10 11 12

Expected Output:
The matrix is not singular.
Inverse of the matrix: 
[[-0.38 -0.1   0.18]
 [-0.15 -0.03  0.08]
 [ 0.08  0.03 -0.02]
 [ 0.31  0.1  -0.11]]
--------------------------------------------------
2025-03-18 00:36:35,763 - PythonTestLogger - ERROR - Test failed for QA4_P7_P8.py on QA4

SRNs: P7/P8

Error:
Traceback (most recent call last):
  File "/Volumes/Aditya SSD/Project/AutomaticPythonTesting/AutomaticPythonTesting/scripts/QA4_P7_P8.py", line 78, in <module>
    is_singular, inv_matrix = analyze_sensor_matrix(A)
                              ^^^^^^^^^^^^^^^^^^^^^^^^
  File "/Volumes/Aditya SSD/Project/AutomaticPythonTesting/AutomaticPythonTesting/scripts/QA4_P7_P8.py", line 68, in analyze_sensor_matrix
    return (is_singular, inv_matrix)
            ^^^^^^^^^^^
NameError: name 'is_singular' is not defined


Test Type: stdin

Test Input:
5
1 0 0 0 0
0 2 1 0 0
0 0 3 1 0
0 0 0 4 1
0 0 0 0 5

Expected Output:
The matrix is not singular.
Inverse of the matrix: 
[[ 1.    0.    0.    0.    0.  ]
 [ 0.    0.5  -0.17  0.04 -0.01]
 [ 0.    0.    0.33 -0.08  0.02]
 [ 0.   -0.   -0.    0.25 -0.05]
 [ 0.    0.    0.    0.    0.2 ]]
--------------------------------------------------
2025-03-18 00:36:36,638 - PythonTestLogger - ERROR - Test failed for QF1_P9_P10.py on QF1

SRNs: P9/P10

Error:
Traceback (most recent call last):
  File "/Volumes/Aditya SSD/Project/AutomaticPythonTesting/AutomaticPythonTesting/scripts/QF1_P9_P10.py", line 119, in <module>
    main()
  File "/Volumes/Aditya SSD/Project/AutomaticPythonTesting/AutomaticPythonTesting/scripts/QF1_P9_P10.py", line 104, in main
    P, L, U = plu_factorization(A)
              ^^^^^^^^^^^^^^^^^^^^
  File "/Volumes/Aditya SSD/Project/AutomaticPythonTesting/AutomaticPythonTesting/scripts/QF1_P9_P10.py", line 89, in plu_factorization
    return P, L, U
           ^
NameError: name 'P' is not defined


Test Type: stdin

Test Input:
2 -1 -2      
-4 6 3
-4 -2 8

Expected Output:
P =
0.0 0.0 1.0
1.0 0.0 0.0
0.0 1.0 0.0

L =
1.0 0.0 0.0
1.0 1.0 0.0
-0.5 -0.2 1.0

U =
-4.0 6.0 3.0
0.0 -8.0 5.0
0.0 0.0 0.8

--------------------------------------------------
2025-03-18 00:36:37,549 - PythonTestLogger - ERROR - Test failed for QF1_P9_P10.py on QF1

SRNs: P9/P10

Error:
Traceback (most recent call last):
  File "/Volumes/Aditya SSD/Project/AutomaticPythonTesting/AutomaticPythonTesting/scripts/QF1_P9_P10.py", line 119, in <module>
    main()
  File "/Volumes/Aditya SSD/Project/AutomaticPythonTesting/AutomaticPythonTesting/scripts/QF1_P9_P10.py", line 104, in main
    P, L, U = plu_factorization(A)
              ^^^^^^^^^^^^^^^^^^^^
  File "/Volumes/Aditya SSD/Project/AutomaticPythonTesting/AutomaticPythonTesting/scripts/QF1_P9_P10.py", line 89, in plu_factorization
    return P, L, U
           ^
NameError: name 'P' is not defined


Test Type: stdin

Test Input:
2  -1   3   4
-4   2  -5  -7
6  -3   8  10
8  -4   9  13

Expected Output:
P =
0.0 0.0 0.0 1.0
0.0 1.0 0.0 0.0
0.0 0.0 1.0 0.0
1.0 0.0 0.0 0.0

L =
1.0 0.0 0.0 0.0
-0.5 1.0 0.0 0.0
0.8 0.0 1.0 0.0
0.2 0.0 0.6 1.0

U =
8.0 -4.0 9.0 13.0
0.0 0.0 -0.5 -0.5
0.0 0.0 1.2 0.2
0.0 0.0 0.0 0.6
--------------------------------------------------
2025-03-18 00:36:38,487 - PythonTestLogger - ERROR - Test failed for QF1_P9_P10.py on QF1

SRNs: P9/P10

Error:
Traceback (most recent call last):
  File "/Volumes/Aditya SSD/Project/AutomaticPythonTesting/AutomaticPythonTesting/scripts/QF1_P9_P10.py", line 119, in <module>
    main()
  File "/Volumes/Aditya SSD/Project/AutomaticPythonTesting/AutomaticPythonTesting/scripts/QF1_P9_P10.py", line 104, in main
    P, L, U = plu_factorization(A)
              ^^^^^^^^^^^^^^^^^^^^
  File "/Volumes/Aditya SSD/Project/AutomaticPythonTesting/AutomaticPythonTesting/scripts/QF1_P9_P10.py", line 89, in plu_factorization
    return P, L, U
           ^
NameError: name 'P' is not defined


Test Type: stdin

Test Input:
1   2   3   4   5
2   3   4   5   6
3   4   5   6   7
4   5   6   7   8
5   6   7   8   9

Expected Output:
P =
0.0 1.0 0.0 0.0 0.0
0.0 0.0 0.0 1.0 0.0
0.0 0.0 1.0 0.0 0.0
0.0 0.0 0.0 0.0 1.0
1.0 0.0 0.0 0.0 0.0

L =
1.0 0.0 0.0 0.0 0.0
0.2 1.0 0.0 0.0 0.0
0.6 0.5 1.0 0.0 0.0
0.4 0.7 0.4 1.0 0.0
0.8 0.2 0.5 0.0 1.0

U =
5.0 6.0 7.0 8.0 9.0
0.0 0.8 1.6 2.4 3.2
0.0 0.0 0.0 0.0 0.0
0.0 0.0 0.0 0.0 0.0
0.0 0.0 0.0 0.0 0.0
--------------------------------------------------
2025-03-18 00:36:38,740 - PythonTestLogger - ERROR - Test failed for QF2_P11_P12.py on QF2

SRNs: P11/P12

Error:
Traceback (most recent call last):
  File "/Volumes/Aditya SSD/Project/AutomaticPythonTesting/AutomaticPythonTesting/scripts/QF2_P11_P12.py", line 71, in <module>
    main()
  File "/Volumes/Aditya SSD/Project/AutomaticPythonTesting/AutomaticPythonTesting/scripts/QF2_P11_P12.py", line 67, in main
    result = check_linear_independence(A)
             ^^^^^^^^^^^^^^^^^^^^^^^^^^^^
  File "/Volumes/Aditya SSD/Project/AutomaticPythonTesting/AutomaticPythonTesting/scripts/QF2_P11_P12.py", line 52, in check_linear_independence
    return is_linearly_independent
           ^^^^^^^^^^^^^^^^^^^^^^^
NameError: name 'is_linearly_independent' is not defined


Test Type: stdin

Test Input:
1 0 0
0 1 0
0 0 1

Expected Output:
True

--------------------------------------------------
2025-03-18 00:36:39,018 - PythonTestLogger - ERROR - Test failed for QF2_P11_P12.py on QF2

SRNs: P11/P12

Error:
Traceback (most recent call last):
  File "/Volumes/Aditya SSD/Project/AutomaticPythonTesting/AutomaticPythonTesting/scripts/QF2_P11_P12.py", line 71, in <module>
    main()
  File "/Volumes/Aditya SSD/Project/AutomaticPythonTesting/AutomaticPythonTesting/scripts/QF2_P11_P12.py", line 67, in main
    result = check_linear_independence(A)
             ^^^^^^^^^^^^^^^^^^^^^^^^^^^^
  File "/Volumes/Aditya SSD/Project/AutomaticPythonTesting/AutomaticPythonTesting/scripts/QF2_P11_P12.py", line 52, in check_linear_independence
    return is_linearly_independent
           ^^^^^^^^^^^^^^^^^^^^^^^
NameError: name 'is_linearly_independent' is not defined


Test Type: stdin

Test Input:
1 2 3
4 5 6
7 8 9

Expected Output:
False
--------------------------------------------------
2025-03-18 00:36:39,269 - PythonTestLogger - ERROR - Test failed for QF2_P11_P12.py on QF2

SRNs: P11/P12

Error:
Traceback (most recent call last):
  File "/Volumes/Aditya SSD/Project/AutomaticPythonTesting/AutomaticPythonTesting/scripts/QF2_P11_P12.py", line 71, in <module>
    main()
  File "/Volumes/Aditya SSD/Project/AutomaticPythonTesting/AutomaticPythonTesting/scripts/QF2_P11_P12.py", line 67, in main
    result = check_linear_independence(A)
             ^^^^^^^^^^^^^^^^^^^^^^^^^^^^
  File "/Volumes/Aditya SSD/Project/AutomaticPythonTesting/AutomaticPythonTesting/scripts/QF2_P11_P12.py", line 52, in check_linear_independence
    return is_linearly_independent
           ^^^^^^^^^^^^^^^^^^^^^^^
NameError: name 'is_linearly_independent' is not defined


Test Type: stdin

Test Input:
1 2
3 4 
5 6

Expected Output:
True
--------------------------------------------------
2025-03-18 00:36:39,540 - PythonTestLogger - ERROR - Test failed for QF2_P11_P12.py on QF2

SRNs: P11/P12

Error:
Traceback (most recent call last):
  File "/Volumes/Aditya SSD/Project/AutomaticPythonTesting/AutomaticPythonTesting/scripts/QF2_P11_P12.py", line 71, in <module>
    main()
  File "/Volumes/Aditya SSD/Project/AutomaticPythonTesting/AutomaticPythonTesting/scripts/QF2_P11_P12.py", line 67, in main
    result = check_linear_independence(A)
             ^^^^^^^^^^^^^^^^^^^^^^^^^^^^
  File "/Volumes/Aditya SSD/Project/AutomaticPythonTesting/AutomaticPythonTesting/scripts/QF2_P11_P12.py", line 52, in check_linear_independence
    return is_linearly_independent
           ^^^^^^^^^^^^^^^^^^^^^^^
NameError: name 'is_linearly_independent' is not defined


Test Type: stdin

Test Input:
1 2 3
4 5 6
7 8 9
10 11 12

Expected Output:
False
--------------------------------------------------
2025-03-18 00:36:39,821 - PythonTestLogger - ERROR - Test failed for QF3_P13_P14.py on QF3

SRNs: P13/P14

Error:
Traceback (most recent call last):
  File "/Volumes/Aditya SSD/Project/AutomaticPythonTesting/AutomaticPythonTesting/scripts/QF3_P13_P14.py", line 85, in <module>
    main()
  File "/Volumes/Aditya SSD/Project/AutomaticPythonTesting/AutomaticPythonTesting/scripts/QF3_P13_P14.py", line 78, in main
    basis, dimension = find_basis_and_dimension(A)
                       ^^^^^^^^^^^^^^^^^^^^^^^^^^^
  File "/Volumes/Aditya SSD/Project/AutomaticPythonTesting/AutomaticPythonTesting/scripts/QF3_P13_P14.py", line 63, in find_basis_and_dimension
    return basis, dimension
           ^^^^^
NameError: name 'basis' is not defined


Test Type: stdin

Test Input:
1 0 0 
0 1 0
0 0 1

Expected Output:
Basis vectors for the column space:
[1.0, 0.0, 0.0]
[0.0, 1.0, 0.0]
[0.0, 0.0, 1.0]
Dimension of the column space: 3
--------------------------------------------------
2025-03-18 00:36:40,089 - PythonTestLogger - ERROR - Test failed for QF3_P13_P14.py on QF3

SRNs: P13/P14

Error:
Traceback (most recent call last):
  File "/Volumes/Aditya SSD/Project/AutomaticPythonTesting/AutomaticPythonTesting/scripts/QF3_P13_P14.py", line 85, in <module>
    main()
  File "/Volumes/Aditya SSD/Project/AutomaticPythonTesting/AutomaticPythonTesting/scripts/QF3_P13_P14.py", line 78, in main
    basis, dimension = find_basis_and_dimension(A)
                       ^^^^^^^^^^^^^^^^^^^^^^^^^^^
  File "/Volumes/Aditya SSD/Project/AutomaticPythonTesting/AutomaticPythonTesting/scripts/QF3_P13_P14.py", line 63, in find_basis_and_dimension
    return basis, dimension
           ^^^^^
NameError: name 'basis' is not defined


Test Type: stdin

Test Input:
1 2
3 4
5 6
7 8

Expected Output:
Basis vectors for the column space:
[1.0, 2.0]
[3.0, 4.0]
[5.0, 6.0]
[7.0, 8.0]
Dimension of the column space: 2
--------------------------------------------------
2025-03-18 00:36:40,340 - PythonTestLogger - ERROR - Test failed for QF3_P13_P14.py on QF3

SRNs: P13/P14

Error:
Traceback (most recent call last):
  File "/Volumes/Aditya SSD/Project/AutomaticPythonTesting/AutomaticPythonTesting/scripts/QF3_P13_P14.py", line 85, in <module>
    main()
  File "/Volumes/Aditya SSD/Project/AutomaticPythonTesting/AutomaticPythonTesting/scripts/QF3_P13_P14.py", line 78, in main
    basis, dimension = find_basis_and_dimension(A)
                       ^^^^^^^^^^^^^^^^^^^^^^^^^^^
  File "/Volumes/Aditya SSD/Project/AutomaticPythonTesting/AutomaticPythonTesting/scripts/QF3_P13_P14.py", line 63, in find_basis_and_dimension
    return basis, dimension
           ^^^^^
NameError: name 'basis' is not defined


Test Type: stdin

Test Input:
1 2 3
4 5 6
7 8 9

Expected Output:
Basis vectors for the column space:
[1.0, 2.0]
[4.0, 5.0]
[7.0, 8.0]
Dimension of the column space: 2

--------------------------------------------------
2025-03-18 00:36:40,629 - PythonTestLogger - ERROR - Test failed for QF3_P13_P14.py on QF3

SRNs: P13/P14

Error:
Traceback (most recent call last):
  File "/Volumes/Aditya SSD/Project/AutomaticPythonTesting/AutomaticPythonTesting/scripts/QF3_P13_P14.py", line 85, in <module>
    main()
  File "/Volumes/Aditya SSD/Project/AutomaticPythonTesting/AutomaticPythonTesting/scripts/QF3_P13_P14.py", line 78, in main
    basis, dimension = find_basis_and_dimension(A)
                       ^^^^^^^^^^^^^^^^^^^^^^^^^^^
  File "/Volumes/Aditya SSD/Project/AutomaticPythonTesting/AutomaticPythonTesting/scripts/QF3_P13_P14.py", line 63, in find_basis_and_dimension
    return basis, dimension
           ^^^^^
NameError: name 'basis' is not defined


Test Type: stdin

Test Input:
1 0 1 2
0 1 1 3
0 0 1 4
0 0 0 0

Expected Output:
Basis vectors for the column space:
[1.0, 0.0, 1.0]
[0.0, 1.0, 1.0]
[0.0, 0.0, 1.0]
[0.0, 0.0, 0.0]
Dimension of the column space: 3
--------------------------------------------------
2025-03-18 00:36:40,893 - PythonTestLogger - ERROR - Test failed for QF3_P13_P14.py on QF3

SRNs: P13/P14

Error:
Traceback (most recent call last):
  File "/Volumes/Aditya SSD/Project/AutomaticPythonTesting/AutomaticPythonTesting/scripts/QF3_P13_P14.py", line 85, in <module>
    main()
  File "/Volumes/Aditya SSD/Project/AutomaticPythonTesting/AutomaticPythonTesting/scripts/QF3_P13_P14.py", line 78, in main
    basis, dimension = find_basis_and_dimension(A)
                       ^^^^^^^^^^^^^^^^^^^^^^^^^^^
  File "/Volumes/Aditya SSD/Project/AutomaticPythonTesting/AutomaticPythonTesting/scripts/QF3_P13_P14.py", line 63, in find_basis_and_dimension
    return basis, dimension
           ^^^^^
NameError: name 'basis' is not defined


Test Type: stdin

Test Input:
3 5 9 5
3 5 4 0
2 5 3 8
4 5 7 1

Expected Output:
Basis vectors for the column space:
[3.0, 5.0, 9.0, 5.0]
[3.0, 5.0, 4.0, 0.0]
[2.0, 5.0, 3.0, 8.0]
[4.0, 5.0, 7.0, 1.0]
Dimension of the column space: 4
--------------------------------------------------
2025-03-18 00:36:41,752 - PythonTestLogger - ERROR - Test failed for QA5_P9_P10.py on QA5

SRNs: P9/P10

Test Type: stdin

Test Input:
2 2
3 1
4 2
9 10

Expected Output:
x =
4.0000 -3.0000
Rank = 2
Nullity = 0


Actual Output:
x =
4.0000 -3.0000

Rank = 2
Nullity = 0
--------------------------------------------------
2025-03-18 00:36:42,601 - PythonTestLogger - ERROR - Test failed for QA5_P9_P10.py on QA5

SRNs: P9/P10

Test Type: stdin

Test Input:
3 3
2 -1 3
1 3 2
4 5 -2
5 6 7


Expected Output:
x =
1.2540 0.8413 1.1111
Rank = 3
Nullity = 0

Actual Output:
x =
1.2540 0.8413 1.1111

Rank = 3
Nullity = 0
--------------------------------------------------
2025-03-18 00:36:43,401 - PythonTestLogger - ERROR - Test failed for QA5_P9_P10.py on QA5

SRNs: P9/P10

Test Type: stdin

Test Input:
4 4
4 -2 1 3
1 1 2 1
3 -1 4 2
2 3 -2 5
20 10 30 15

Expected Output:
x =
-10.8065 -6.9355 6.7742 14.1935
Rank = 4
Nullity = 0

Actual Output:
x =
-10.8065 -6.9355 6.7742 14.1935

Rank = 4
Nullity = 0
--------------------------------------------------
2025-03-18 00:36:43,673 - PythonTestLogger - ERROR - Test failed for QA6_P11_P12.py on QA6

SRNs: P11/P12

Error:
Traceback (most recent call last):
  File "/Volumes/Aditya SSD/Project/AutomaticPythonTesting/AutomaticPythonTesting/scripts/QA6_P11_P12.py", line 3, in <module>
    from sympy import Matrix
ModuleNotFoundError: No module named 'sympy'


Test Type: stdin

Test Input:
2 2
1 2
0 1
2 1
2
3

Expected Output:
P' =
8.0
3.0

RREF =
1.0 0.0
0.0 1.0

T^-1 =
1.000 -2.000
0.000 1.000
--------------------------------------------------
2025-03-18 00:36:43,943 - PythonTestLogger - ERROR - Test failed for QA6_P11_P12.py on QA6

SRNs: P11/P12

Error:
Traceback (most recent call last):
  File "/Volumes/Aditya SSD/Project/AutomaticPythonTesting/AutomaticPythonTesting/scripts/QA6_P11_P12.py", line 3, in <module>
    from sympy import Matrix
ModuleNotFoundError: No module named 'sympy'


Test Type: stdin

Test Input:
3 3
3 1 2
4 2 1
1 2 3
3 1
1
0
1


Expected Output:
P' =
5.0
5.0
4.0

RREF =
1.0 0.0 0.0
0.0 1.0 0.0
0.0 0.0 1.0

T^-1 =
0.308 0.077 -0.231
-0.846 0.538 0.385
0.462 -0.385 0.154
--------------------------------------------------
2025-03-18 00:36:44,200 - PythonTestLogger - ERROR - Test failed for QA6_P11_P12.py on QA6

SRNs: P11/P12

Error:
Traceback (most recent call last):
  File "/Volumes/Aditya SSD/Project/AutomaticPythonTesting/AutomaticPythonTesting/scripts/QA6_P11_P12.py", line 3, in <module>
    from sympy import Matrix
ModuleNotFoundError: No module named 'sympy'


Test Type: stdin

Test Input:
4 4
2 3 1 4
1 5 3 2
4 2 6 5
3 1 2 3
4 1
5
6
7
8

Expected Output:
P' =
67.0
72.0
114.0
59.0

RREF =
1.0 0.0 0.0 0.0
0.0 1.0 0.0 0.0
0.0 0.0 1.0 0.0
0.0 0.0 0.0 1.0

T^-1 =
-0.407 0.185 -0.370 1.037
-0.037 0.259 -0.185 0.185
-0.148 0.037 0.259 -0.259
0.519 -0.296 0.259 -0.593

--------------------------------------------------
2025-03-18 00:36:44,467 - PythonTestLogger - ERROR - Test failed for QA7_P13_P14.py on QA7

SRNs: P13/P14

Error:
Traceback (most recent call last):
  File "/Volumes/Aditya SSD/Project/AutomaticPythonTesting/AutomaticPythonTesting/scripts/QA7_P13_P14.py", line 3, in <module>
    from sympy import Matrix
ModuleNotFoundError: No module named 'sympy'


Test Type: stdin

Test Input:
3 4
1 -1 0 0
0 1 -1 0
0 0 1 -1

Expected Output:
RREF =
1.0 0.0 0.0 -1.0
0.0 1.0 0.0 -1.0
0.0 0.0 1.0 -1.0

Rank = 3
Nullity = 1
--------------------------------------------------
2025-03-18 00:36:44,731 - PythonTestLogger - ERROR - Test failed for QA7_P13_P14.py on QA7

SRNs: P13/P14

Error:
Traceback (most recent call last):
  File "/Volumes/Aditya SSD/Project/AutomaticPythonTesting/AutomaticPythonTesting/scripts/QA7_P13_P14.py", line 3, in <module>
    from sympy import Matrix
ModuleNotFoundError: No module named 'sympy'


Test Type: stdin

Test Input:
3 3
1 2 3
4 5 6
7 8 10

Expected Output:
RREF =
1.0 0.0 0.0
0.0 1.0 0.0
0.0 0.0 1.0

Rank = 3
Nullity = 0
--------------------------------------------------
2025-03-18 00:36:45,000 - PythonTestLogger - ERROR - Test failed for QA7_P13_P14.py on QA7

SRNs: P13/P14

Error:
Traceback (most recent call last):
  File "/Volumes/Aditya SSD/Project/AutomaticPythonTesting/AutomaticPythonTesting/scripts/QA7_P13_P14.py", line 3, in <module>
    from sympy import Matrix
ModuleNotFoundError: No module named 'sympy'


Test Type: stdin

Test Input:
4 5
1 0 -1 2 3
0 1 1 0 -1
1 1 0 -1 4
2 -1 3 1 0

Expected Output:
RREF =
1.0 0.0 0.0 0.0 2.8
0.0 1.0 0.0 0.0 0.5
0.0 0.0 1.0 0.0 -1.5
0.0 0.0 0.0 1.0 -0.7

Rank = 4
Nullity = 1

--------------------------------------------------
2025-03-18 00:36:45,255 - PythonTestLogger - ERROR - Test failed for QA8_P15_P16.py on QA8

SRNs: P15/P16

Error:
Traceback (most recent call last):
  File "/Volumes/Aditya SSD/Project/AutomaticPythonTesting/AutomaticPythonTesting/scripts/QA8_P15_P16.py", line 3, in <module>
    from sympy import Matrix
ModuleNotFoundError: No module named 'sympy'


Test Type: stdin

Test Input:
2 2
2 1
3 4
2 2
5 6
7 8

Expected Output:
C =
2.6 3.2
-0.2 -0.4

RREF =
1.0 0.0
0.0 1.0

Rank = 2
Nullity = 0
--------------------------------------------------
2025-03-18 00:36:45,518 - PythonTestLogger - ERROR - Test failed for QA8_P15_P16.py on QA8

SRNs: P15/P16

Error:
Traceback (most recent call last):
  File "/Volumes/Aditya SSD/Project/AutomaticPythonTesting/AutomaticPythonTesting/scripts/QA8_P15_P16.py", line 3, in <module>
    from sympy import Matrix
ModuleNotFoundError: No module named 'sympy'


Test Type: stdin

Test Input:
3 3
3 1 2
4 2 1
1 2 3
3 2
6 9
3 7
8 5


Expected Output:
C =
0.2 2.2
-0.4 -1.9
2.8 2.2

RREF =
1.0 0.0 0.0
0.0 1.0 0.0
0.0 0.0 1.0

Rank = 3
Nullity = 0
--------------------------------------------------
2025-03-18 00:36:45,783 - PythonTestLogger - ERROR - Test failed for QA8_P15_P16.py on QA8

SRNs: P15/P16

Error:
Traceback (most recent call last):
  File "/Volumes/Aditya SSD/Project/AutomaticPythonTesting/AutomaticPythonTesting/scripts/QA8_P15_P16.py", line 3, in <module>
    from sympy import Matrix
ModuleNotFoundError: No module named 'sympy'


Test Type: stdin

Test Input:
4 4
2 3 1 4
1 5 3 2
4 2 6 5
3 1 2 3
4 2
5 6
7 8
9 10
11 12

Expected Output:
C =
7.3 7.8
2.0 2.2
-1.0 -1.1
-3.7 -3.8

RREF =
1.0 0.0 0.0 0.0
0.0 1.0 0.0 0.0
0.0 0.0 1.0 0.0
0.0 0.0 0.0 1.0

Rank = 4
Nullity = 0

--------------------------------------------------
2025-03-18 00:36:46,055 - PythonTestLogger - ERROR - Test failed for QF4_P15_P16.py on QF4

SRNs: P15/P16

Test Type: stdin

Test Input:
2
2 -1
1 3

Expected Output:
U =
1.0 0.0
0.0 1.0

C =
0.4 0.1
-0.1 0.3

A^-1 =
0.4 0.1
-0.1 0.3


Actual Output:
U =
1.0 0.0
0.0 1.0

C =
0.4 0.1
-0.1 0.3

A^-1 =
0.4 0.1
-0.1 0.3
--------------------------------------------------
2025-03-18 00:36:46,322 - PythonTestLogger - ERROR - Test failed for QF4_P15_P16.py on QF4

SRNs: P15/P16

Test Type: stdin

Test Input:
3
3 1 2
4 2 1
1 2 3

Expected Output:
U =
1.0 0.0 0.0
0.0 1.0 0.0
0.0 0.0 1.0

C =
0.3 0.1 -0.2
-0.8 0.5 0.4
0.5 -0.4 0.2

A^-1 =
0.3 0.1 -0.2
-0.8 0.5 0.4
0.5 -0.4 0.2


Actual Output:
U =
1.0 0.0 0.0
0.0 1.0 0.0
0.0 0.0 1.0

C =
0.3 0.1 -0.2
-0.8 0.5 0.4
0.5 -0.4 0.2

A^-1 =
0.3 0.1 -0.2
-0.8 0.5 0.4
0.5 -0.4 0.2
--------------------------------------------------
2025-03-18 00:36:46,854 - PythonTestLogger - ERROR - Test failed for QF5_P17_P18.py on QF5

SRNs: P17/P18

Test Type: stdin

Test Input:
2
2 -1 1
1 3 2

Expected Output:
U =
1.0 -0.5 
0.0 1.0 

x =
0.7 0.4

Actual Output:
U =
1.0 -0.5
0.0 1.0

x =
0.7 0.4
--------------------------------------------------
2025-03-18 00:36:47,634 - PythonTestLogger - ERROR - Test failed for QF6_P19_P20.py on QF6

SRNs: P19/P20

Error:
Traceback (most recent call last):
  File "/Volumes/Aditya SSD/Project/AutomaticPythonTesting/AutomaticPythonTesting/scripts/QF6_P19_P20.py", line 3, in <module>
    from sympy import Matrix
ModuleNotFoundError: No module named 'sympy'


Test Type: stdin

Test Input:
3 3
1 2 -1
2 4 -2
3 6 -3

Expected Output:
RREF =
1.0 2.0 -1.0
0.0 0.0 0.0
0.0 0.0 0.0
--------------------------------------------------
2025-03-18 00:36:47,896 - PythonTestLogger - ERROR - Test failed for QF6_P19_P20.py on QF6

SRNs: P19/P20

Error:
Traceback (most recent call last):
  File "/Volumes/Aditya SSD/Project/AutomaticPythonTesting/AutomaticPythonTesting/scripts/QF6_P19_P20.py", line 3, in <module>
    from sympy import Matrix
ModuleNotFoundError: No module named 'sympy'


Test Type: stdin

Test Input:
3 3
1 2 3
0 1 4
5 6 0

Expected Output:
RREF =
1.0 0.0 0.0
0.0 1.0 0.0
0.0 0.0 1.0
--------------------------------------------------
2025-03-18 00:36:48,170 - PythonTestLogger - ERROR - Test failed for QF6_P19_P20.py on QF6

SRNs: P19/P20

Error:
Traceback (most recent call last):
  File "/Volumes/Aditya SSD/Project/AutomaticPythonTesting/AutomaticPythonTesting/scripts/QF6_P19_P20.py", line 3, in <module>
    from sympy import Matrix
ModuleNotFoundError: No module named 'sympy'


Test Type: stdin

Test Input:
3 4
4 7 2 5
2 6 5 8
1 3 1 4

Expected Output:
RREF =
1.0 0.0 0.0 -2.6
0.0 1.0 0.0 2.2
0.0 0.0 1.0 0.0
--------------------------------------------------
